<?xml version="1.0" encoding="utf-8"?>
<!-- This URDF was automatically created by SolidWorks to URDF Exporter! Originally created by Stephen Brawner (brawner@gmail.com) 
     Commit Version: 1.6.0-4-g7f85cfe  Build Version: 1.6.7995.38578
     For more information, please see http://wiki.ros.org/sw_urdf_exporter -->
<robot name="pallet_jack">

  <link name="base_link">
    <inertial>
      <origin xyz="0 0 0" rpy="0 0 0" />
      <mass value="647.44" />
      <inertia ixx="236.64" ixy="-2.2442E-15" ixz="-1.1636E-14" iyy="111.96" iyz="-4.5499" izz="204.96" />
    </inertial>
    <visual>
      <origin xyz="0 0 0" rpy="0 0 0" />
      <geometry>
        <mesh filename="package://pallet_jack_description/pallet_jack/meshes/base_link.STL" />
      </geometry>
      <material name="">
        <color rgba="1 1 0.50196 1" />
      </material>
    </visual>
    <collision>
      <origin xyz="0 0 0" rpy="0 0 0" />
      <geometry>
        <mesh filename="package://pallet_jack_description/pallet_jack/meshes/base_link.STL" />
      </geometry>
    </collision>
  </link>

  <link name="steering_wheel_link">
    <inertial>
      <origin xyz="-2.2204E-16 -3.6739E-17 0.5125" rpy="0 0 0" />
      <mass value="44.179" />
      <inertia ixx="1.6866" ixy="-2.3207E-34" ixz="3.1077E-16" iyy="1.6866" iyz="7.4913E-33" izz="0.49701" />
    </inertial>
    <visual>
      <origin xyz="0 0 0" rpy="0 0 0" />
      <geometry>
        <mesh filename="package://pallet_jack_description/pallet_jack/meshes/steering_wheel_link.STL" />
      </geometry>
      <material name="">
        <color rgba="0.79216 0.81961 0.93333 1" />
      </material>
    </visual>
  </link>
  
  <joint name="steering_wheel" type="revolute">
    <origin xyz="0 0.2925 0" rpy="3.1416 0 1.5708" />
    <parent link="base_link" />
    <child link="steering_wheel_link" />
    <axis xyz="0 0 1" />
    <limit lower="-1.571" upper="1.571" effort="0" velocity="0" />
  </joint>  

  <link name="drive_wheel_link">
    <inertial>
      <origin xyz="0 1.3878E-17 -1.1504E-17" rpy="0 0 0" />
      <mass value="37.699" />
      <inertia ixx="0.65973" ixy="0" ixz="1.1046E-33" iyy="0.65973" iyz="-2.1856E-33" izz="0.75398" />
    </inertial>
    <visual>
      <origin xyz="0 0 0" rpy="0 0 0" />
      <geometry>
        <mesh filename="package://pallet_jack_description/pallet_jack/meshes/drive_wheel_link.STL" />
      </geometry>
      <material name="">
        <color rgba="0.50196 0.50196 0.50196 1" />
      </material>
    </visual>
    <collision>
      <origin xyz="0 0 0" rpy="0 0 0" />
      <geometry>
        <mesh filename="package://pallet_jack_description/pallet_jack/meshes/drive_wheel_link.STL" />
      </geometry>
    </collision>
  </link>
  
  <joint name="drive_wheel" type="continuous">
    <origin xyz="0 0 0.695" rpy="1.5708 0 0" />
    <parent link="steering_wheel_link" />
    <child link="drive_wheel_link" />
    <axis xyz="0 0 -1" />
    <!--limit lower="0" upper="0" effort="0" velocity="0" /-->
  </joint>
  
  <link name="lidar">
    <inertial>
      <origin xyz="-2.8561E-18 9.2635E-18 0.013281" rpy="0 0 0" />
      <mass value="1.406" />
      <inertia ixx="0.0028094" ixy="-2.5675E-35" ixz="-1.9299E-19" iyy="0.0028094" iyz="2.3677E-20" izz="0.0029459" />
    </inertial>
    <visual>
      <origin xyz="0 0 0" rpy="0 0 0" />
      <geometry>
        <mesh filename="package://pallet_jack_description/pallet_jack/meshes/lidar.STL" />
      </geometry>
      <material name="">
        <color rgba="1 0.50196 0.50196 1" />
      </material>
    </visual>
  </link>
  
  <joint name="lidar_joint" type="fixed">
    <origin xyz="0 -0.817499999999999 1.03" rpy="0 0 0" />
    <parent link="base_link" />
    <child link="lidar" />
    <axis xyz="0 0 0" />
  </joint>  
  
  <link name="zed_cam_1">
    <inertial>
      <origin xyz="0.025 -2.2037E-18 0" rpy="0 0 0" />
      <mass value="0.615" />
      <inertia ixx="0.0032296" ixy="4.8692E-19" ixz="4.0115E-18" iyy="0.00025625" iyz="-1.2057E-18" izz="0.0032296" />
    </inertial>
    <visual>
      <origin xyz="0 0 0" rpy="0 0 0" />
      <geometry>
        <mesh filename="package://pallet_jack_description/pallet_jack/meshes/zed_cam_1.STL" />
      </geometry>
      <material name="">
        <color rgba="1 0.50196 0.50196 1" />
      </material>
    </visual>
  </link>
  
  <joint name="zed_cam_1_joint" type="fixed">
    <origin xyz="0 -0.8675 0.428252347032464" rpy="0 0.349065850398863 -1.5707963267949" />
    <parent link="base_link" />
    <child link="zed_cam_1" />
    <axis xyz="0 0 0" />
  </joint>
  
  <link name="zed_cam_2">
    <inertial>
      <origin xyz="0.025 2.7546E-17 -2.2204E-16" rpy="0 0 0" />
      <mass value="0.615" />
      <inertia ixx="0.0032296" ixy="1.0147E-19" ixz="-4.4452E-18" iyy="0.00025625" iyz="8.838E-20" izz="0.0032296" />
    </inertial>
    <visual>
      <origin xyz="0 0 0" rpy="0 0 0" />
      <geometry>
        <mesh filename="package://pallet_jack_description/pallet_jack/meshes/zed_cam_2.STL" />
      </geometry>
      <material name="">
        <color rgba="1 0.50196 0.50196 1" />
      </material>
    </visual>
  </link>
  
  <joint name="zed_cam_2_joint" type="fixed">
    <origin xyz="0 0.4925 0.0699999999999998" rpy="0 0.174532925199438 1.5707963267949" />
    <parent link="base_link" />
    <child link="zed_cam_2" />
    <axis xyz="0 0 0" />
  </joint>  
  
  <!-- Robot Footprint -->
  <link name="base_footprint"/>
  
  <joint name="base_fp_dlt" type="fixed">
    <origin xyz="0 -0.45 -0.895" rpy="0 0 0" />
    <parent link="base_link" />
    <child link="base_footprint" />
    <axis xyz="0 0 0" />
  </joint>  
  
  <link name="caster_1">
    <inertial>
      <origin xyz="0 0 0" rpy="0 0 0" />
      <mass value="1.0227" />
      <inertia ixx="0.0015979" ixy="0" ixz="0" iyy="0.0015979" iyz="0" izz="0.0015979" />
    </inertial>
    <visual>
      <origin xyz="0 0 0" rpy="0 0 0" />
      <geometry>
        <mesh filename="package://pallet_jack_description/pallet_jack/meshes/caster_1.STL" />
      </geometry>
      <material name="">
        <color rgba="0.50196 0.50196 0.50196 1" />
      </material>
    </visual>
    <collision>
      <origin xyz="0 0 0" rpy="0 0 0" />
      <geometry>
        <mesh filename="package://pallet_jack_description/pallet_jack/meshes/caster_1.STL" />
      </geometry>
    </collision>
  </link>
  
  <joint name="caster_1_joint" type="fixed">
    <origin xyz="0.2925 0.2925 -0.8325" rpy="1.5708 0 0" />
    <parent link="base_link" />
    <child link="caster_1" />
    <axis xyz="0 0 0" />
  </joint>
  
  <link name="caster_2">
    <inertial>
      <origin xyz="0 0 0" rpy="0 0 0" />
      <mass value="1.0227" />
      <inertia ixx="0.0015979" ixy="0" ixz="0" iyy="0.0015979" iyz="0" izz="0.0015979" />
    </inertial>
    <visual>
      <origin xyz="0 0 0" rpy="0 0 0" />
      <geometry>
        <mesh filename="package://pallet_jack_description/pallet_jack/meshes/caster_2.STL" />
      </geometry>
      <material name="">
        <color rgba="0.50196 0.50196 0.50196 1" />
      </material>
    </visual>
    <collision>
      <origin xyz="0 0 0" rpy="0 0 0" />
      <geometry>
        <mesh filename="package://pallet_jack_description/pallet_jack/meshes/caster_2.STL" />
      </geometry>
    </collision>
  </link>
  
  <joint name="caster_2_joint" type="fixed">
    <origin xyz="-0.2925 0.2925 -0.8325" rpy="1.5708 0 0" />
    <parent link="base_link" />
    <child link="caster_2" />
    <axis xyz="0 0 0" />
  </joint>
  
  <link name="caster_3">
    <inertial>
      <origin xyz="0 0 0" rpy="0 0 0" />
      <mass value="1.0227" />
      <inertia ixx="0.0015979" ixy="0" ixz="0" iyy="0.0015979" iyz="0" izz="0.0015979" />
    </inertial>
    <visual>
      <origin xyz="0 0 0" rpy="0 0 0" />
      <geometry>
        <mesh filename="package://pallet_jack_description/pallet_jack/meshes/caster_3.STL" />
      </geometry>
      <material name="">
        <color rgba="0.50196 0.50196 0.50196 1" />
      </material>
    </visual>
    <collision>
      <origin xyz="0 0 0" rpy="0 0 0" />
      <geometry>
        <mesh filename="package://pallet_jack_description/pallet_jack/meshes/caster_3.STL" />
      </geometry>
    </collision>
  </link>
  
  <joint name="caster_3_joint" type="fixed">
    <origin xyz="0.2325 -1.7275 -0.8325" rpy="1.5708 0 0" />
    <parent link="base_link" />
    <child link="caster_3" />
    <axis xyz="0 0 0" />
  </joint>
  
  <link name="caster_4">
    <inertial>
      <origin xyz="0 0 0" rpy="0 0 0" />
      <mass value="1.0227" />
      <inertia ixx="0.0015979" ixy="0" ixz="0" iyy="0.0015979" iyz="0" izz="0.0015979" />
    </inertial>
    <visual>
      <origin xyz="0 0 0" rpy="0 0 0" />
      <geometry>
        <mesh filename="package://pallet_jack_description/pallet_jack/meshes/caster_4.STL" />
      </geometry>
      <material name="">
        <color rgba="0.50196 0.50196 0.50196 1" />
      </material>
    </visual>
    <collision>
      <origin xyz="0 0 0" rpy="0 0 0" />
      <geometry>
        <mesh filename="package://pallet_jack_description/pallet_jack/meshes/caster_4.STL" />
      </geometry>
    </collision>
  </link>
  
  <joint name="caster_4_joint"
    type="fixed">
    <origin xyz="-0.2325 -1.7275 -0.8325" rpy="1.5708 0 0" />
    <parent link="base_link" />
    <child link="caster_4" />
    <axis xyz="0 0 0" />
  </joint>

  <!-- Set up sensors in gazebo: -->

  <!-- IMUs -->
  <gazebo reference="zed_cam_1">
    <sensor name="imu_sensor_zed_1" type="imu">
      <plugin filename="libgazebo_ros_imu_sensor.so" name="imu_plugin">
        <ros>
          <namespace>/demo</namespace>
          <remapping>~/out:=imu</remapping>
        </ros>
        <initial_orientation_as_reference>false</initial_orientation_as_reference>
      </plugin>
      <always_on>true</always_on>
      <update_rate>100</update_rate>
      <visualize>true</visualize>
      <imu>
        <angular_velocity>
          <x>
            <noise type="gaussian">
              <mean>0.0</mean>
              <stddev>2e-4</stddev>
              <bias_mean>0.0000075</bias_mean>
              <bias_stddev>0.0000008</bias_stddev>
            </noise>
          </x>
          <y>
            <noise type="gaussian">
              <mean>0.0</mean>
              <stddev>2e-4</stddev>
              <bias_mean>0.0000075</bias_mean>
              <bias_stddev>0.0000008</bias_stddev>
            </noise>
          </y>
          <z>
            <noise type="gaussian">
              <mean>0.0</mean>
              <stddev>2e-4</stddev>
              <bias_mean>0.0000075</bias_mean>
              <bias_stddev>0.0000008</bias_stddev>
            </noise>
          </z>
        </angular_velocity>
        <linear_acceleration>
          <x>
            <noise type="gaussian">
              <mean>0.0</mean>
              <stddev>1.7e-2</stddev>
              <bias_mean>0.1</bias_mean>
              <bias_stddev>0.001</bias_stddev>
            </noise>
          </x>
          <y>
            <noise type="gaussian">
              <mean>0.0</mean>
              <stddev>1.7e-2</stddev>
              <bias_mean>0.1</bias_mean>
              <bias_stddev>0.001</bias_stddev>
            </noise>
          </y>
          <z>
            <noise type="gaussian">
              <mean>0.0</mean>
              <stddev>1.7e-2</stddev>
              <bias_mean>0.1</bias_mean>
              <bias_stddev>0.001</bias_stddev>
            </noise>
          </z>
        </linear_acceleration>
      </imu>
    </sensor>
  </gazebo>

  <gazebo reference="zed_cam_2">
    <sensor name="imu_sensor_zed_2" type="imu">
      <plugin filename="libgazebo_ros_imu_sensor.so" name="imu_plugin">
        <ros>
          <namespace>/demo</namespace>
          <remapping>~/out:=imu</remapping>
        </ros>
        <initial_orientation_as_reference>false</initial_orientation_as_reference>
      </plugin>
      <always_on>true</always_on>
      <update_rate>100</update_rate>
      <visualize>true</visualize>
      <imu>
        <angular_velocity>
          <x>
            <noise type="gaussian">
              <mean>0.0</mean>
              <stddev>2e-4</stddev>
              <bias_mean>0.0000075</bias_mean>
              <bias_stddev>0.0000008</bias_stddev>
            </noise>
          </x>
          <y>
            <noise type="gaussian">
              <mean>0.0</mean>
              <stddev>2e-4</stddev>
              <bias_mean>0.0000075</bias_mean>
              <bias_stddev>0.0000008</bias_stddev>
            </noise>
          </y>
          <z>
            <noise type="gaussian">
              <mean>0.0</mean>
              <stddev>2e-4</stddev>
              <bias_mean>0.0000075</bias_mean>
              <bias_stddev>0.0000008</bias_stddev>
            </noise>
          </z>
        </angular_velocity>
        <linear_acceleration>
          <x>
            <noise type="gaussian">
              <mean>0.0</mean>
              <stddev>1.7e-2</stddev>
              <bias_mean>0.1</bias_mean>
              <bias_stddev>0.001</bias_stddev>
            </noise>
          </x>
          <y>
            <noise type="gaussian">
              <mean>0.0</mean>
              <stddev>1.7e-2</stddev>
              <bias_mean>0.1</bias_mean>
              <bias_stddev>0.001</bias_stddev>
            </noise>
          </y>
          <z>
            <noise type="gaussian">
              <mean>0.0</mean>
              <stddev>1.7e-2</stddev>
              <bias_mean>0.1</bias_mean>
              <bias_stddev>0.001</bias_stddev>
            </noise>
          </z>
        </linear_acceleration>
      </imu>
    </sensor>
  </gazebo>

  <gazebo reference="lidar">
    <sensor name="imu_sensor_lidar" type="imu">
      <plugin filename="libgazebo_ros_imu_sensor.so" name="imu_plugin">
        <ros>
          <namespace>/demo</namespace>
          <remapping>~/out:=imu</remapping>
        </ros>
        <initial_orientation_as_reference>false</initial_orientation_as_reference>
      </plugin>
      <always_on>true</always_on>
      <update_rate>100</update_rate>
      <visualize>true</visualize>
      <imu>
        <angular_velocity>
          <x>
            <noise type="gaussian">
              <mean>0.0</mean>
              <stddev>2e-4</stddev>
              <bias_mean>0.0000075</bias_mean>
              <bias_stddev>0.0000008</bias_stddev>
            </noise>
          </x>
          <y>
            <noise type="gaussian">
              <mean>0.0</mean>
              <stddev>2e-4</stddev>
              <bias_mean>0.0000075</bias_mean>
              <bias_stddev>0.0000008</bias_stddev>
            </noise>
          </y>
          <z>
            <noise type="gaussian">
              <mean>0.0</mean>
              <stddev>2e-4</stddev>
              <bias_mean>0.0000075</bias_mean>
              <bias_stddev>0.0000008</bias_stddev>
            </noise>
          </z>
        </angular_velocity>
        <linear_acceleration>
          <x>
            <noise type="gaussian">
              <mean>0.0</mean>
              <stddev>1.7e-2</stddev>
              <bias_mean>0.1</bias_mean>
              <bias_stddev>0.001</bias_stddev>
            </noise>
          </x>
          <y>
            <noise type="gaussian">
              <mean>0.0</mean>
              <stddev>1.7e-2</stddev>
              <bias_mean>0.1</bias_mean>
              <bias_stddev>0.001</bias_stddev>
            </noise>
          </y>
          <z>
            <noise type="gaussian">
              <mean>0.0</mean>
              <stddev>1.7e-2</stddev>
              <bias_mean>0.1</bias_mean>
              <bias_stddev>0.001</bias_stddev>
            </noise>
          </z>
        </linear_acceleration>
      </imu>
    </sensor>
  </gazebo>

  <!-- Zed cameras -->

  <!-- Lidar -->
  <!-- <xacro:include filename="package://velodyne_simulator/veloyne_description/urdf/VLP-16.urdf.xacro"/>
  <VLP-16 parent="lidar" name="velodyne" topic="/velodyne_points" hz="10" samples="440" gpu="false">
    <origin xyz="0 0 0" rpy="0 0 0" />
  </VLP-16> -->

  <!-- Tricycle Drive -->

</robot>