<?xml version="1.0" encoding="utf-8"?>
<!-- This URDF was automatically created by SolidWorks to URDF Exporter! Originally created by Stephen Brawner (brawner@gmail.com) 
     Commit Version: 1.6.0-4-g7f85cfe  Build Version: 1.6.7995.38578
     For more information, please see http://wiki.ros.org/sw_urdf_exporter -->
<robot name="pallet_jack">
  <link name="base_link">
    <inertial>
      <origin xyz="1.0048E-18 -0.22626 -0.36526" rpy="0 0 0" />
      <mass value="647.44" />
      <inertia ixx="236.64" ixy="-2.2442E-15" ixz="-1.1636E-14" iyy="111.96" iyz="-4.5499" izz="204.96" />
    </inertial>
    <visual>
      <origin xyz="0 0 0" rpy="0 0 0" />
      <geometry>
        <mesh filename="meshes/base_link.STL" />
      </geometry>
      <material name="">
        <color rgba="1 1 0.50196 1" />
      </material>
    </visual>
    <collision>
      <origin xyz="0 0 0" rpy="0 0 0" />
      <geometry>
        <mesh filename="meshes/base_link.STL" />
      </geometry>
    </collision>
  </link>

  <link name="steering_wheel_link">
    <inertial>
      <origin xyz="-2.2204E-16 -3.6739E-17 0.5125" rpy="0 0 0" />
      <mass value="44.179" />
      <inertia ixx="1.6866" ixy="-2.3207E-34" ixz="3.1077E-16" iyy="1.6866" iyz="7.4913E-33" izz="0.49701" />
    </inertial>
    <visual>
      <origin xyz="0 0 0" rpy="0 0 0" />
      <geometry>
        <mesh filename="meshes/steering_wheel_link.STL" />
      </geometry>
      <material name="">
        <color rgba="0.79216 0.81961 0.93333 1" />
      </material>
    </visual>
  </link>
  
  <joint name="steering_wheel" type="revolute">
    <origin xyz="0 0.2925 0" rpy="3.1416 0 1.5708" />
    <parent link="base_link" />
    <child link="steering_wheel_link" />
    <axis xyz="0 0 1" />
    <limit lower="0" upper="0" effort="0" velocity="0" />
  </joint>  

  <link name="drive_wheel_link">
    <inertial>
      <origin xyz="0 1.3878E-17 -1.1504E-17" rpy="0 0 0" />
      <mass value="37.699" />
      <inertia ixx="0.65973" ixy="0" ixz="1.1046E-33" iyy="0.65973" iyz="-2.1856E-33" izz="0.75398" />
    </inertial>
    <visual>
      <origin xyz="0 0 0" rpy="0 0 0" />
      <geometry>
        <mesh filename="meshes/drive_wheel_link.STL" />
      </geometry>
      <material name="">
        <color rgba="0.50196 0.50196 0.50196 1" />
      </material>
    </visual>
    <collision>
      <origin xyz="0 0 0" rpy="0 0 0" />
      <geometry>
        <mesh filename="meshes/drive_wheel_link.STL" />
      </geometry>
    </collision>
  </link>
  
  <joint name="drive_wheel" type="continuous">
    <origin xyz="0 0 0.695" rpy="1.5708 0 0" />
    <parent link="steering_wheel_link" />
    <child link="drive_wheel_link" />
    <axis xyz="0 0 -1" />
    <limit lower="0" upper="0" effort="0" velocity="0" />
  </joint>
  
  <link name="lidar">
    <visual>
      <origin xyz="0 0 0" rpy="0 0 0" />
      <geometry>
        <mesh filename="meshes/lidar.STL" />
      </geometry>
      <material name="">
        <color rgba="1 0.50196 0.50196 1" />
      </material>
    </visual>
  </link>
  
  <joint name="lidar_joint" type="fixed">
    <origin xyz="0 -0.817499999999999 1.03" rpy="0 0 0" />
    <parent link="base_link" />
    <child link="lidar" />
    <axis xyz="0 0 0" />
  </joint>  
  
  <link name="zed_cam_1">
    <inertial>
      <origin xyz="0.025 -2.2037E-18 0" rpy="0 0 0" />
      <mass value="0.615" />
      <inertia ixx="0.0032296" ixy="4.8692E-19" ixz="4.0115E-18" iyy="0.00025625" iyz="-1.2057E-18" izz="0.0032296" />
    </inertial>
    <visual>
      <origin xyz="0 0 0" rpy="0 0 0" />
      <geometry>
        <mesh filename="meshes/zed_cam_1.STL" />
      </geometry>
      <material name="">
        <color rgba="1 0.50196 0.50196 1" />
      </material>
    </visual>
  </link>
  
  <joint name="zed_dlt1" type="fixed">
    <origin xyz="0 -0.8675 0.428252347032464" rpy="0 0.349065850398863 -1.5707963267949" />
    <parent link="base_link" />
    <child link="zed_cam_1" />
    <axis xyz="0 0 0" />
  </joint>
  
  <link name="zed_cam_2">
    <visual>
      <origin xyz="0 0 0" rpy="0 0 0" />
      <geometry>
        <mesh filename="meshes/zed_cam_2.STL" />
      </geometry>
      <material name="">
        <color rgba="1 0.50196 0.50196 1" />
      </material>
    </visual>
  </link>
  
  <joint name="zed_cam_2_joint" type="fixed">
    <origin xyz="0 0.4925 0.0699999999999998" rpy="0 0.174532925199438 1.5707963267949" />
    <parent link="base_link" />
    <child link="zed_cam_2" />
    <axis xyz="0 0 0" />
  </joint>  
  
  <!-- Robot Footprint -->
  <link name="base_footprint"/>
  
  <joint name="base_fp_dlt" type="fixed">
    <origin xyz="0 -0.45 -0.895" rpy="0 0 0" />
    <parent link="base_link" />
    <child link="base_footprint" />
    <axis xyz="0 0 0" />
  </joint>  
  
  <link name="caster_1">
    <visual>
      <origin xyz="0 0 0" rpy="0 0 0" />
      <geometry>
        <mesh filename="meshes/caster_1.STL" />
      </geometry>
      <material name="">
        <color rgba="0.50196 0.50196 0.50196 1" />
      </material>
    </visual>
  </link>
  
  <joint name="caster_1_joint" type="fixed">
    <origin xyz="0.2925 0.2925 -0.8325" rpy="1.5708 0 0" />
    <parent link="base_link" />
    <child link="caster_1" />
    <axis xyz="0 0 0" />
  </joint>
  
  <link name="caster_2">
    <visual>
      <origin xyz="0 0 0" rpy="0 0 0" />
      <geometry>
        <mesh filename="meshes/caster_2.STL" />
      </geometry>
      <material name="">
        <color rgba="0.50196 0.50196 0.50196 1" />
      </material>
    </visual>
  </link>
  
  <joint name="caster_2_joint" type="fixed">
    <origin xyz="-0.2925 0.2925 -0.8325" rpy="1.5708 0 0" />
    <parent link="base_link" />
    <child link="caster_2" />
    <axis xyz="0 0 0" />
  </joint>
  
  <link name="caster_3">
    <visual>
      <origin xyz="0 0 0" rpy="0 0 0" />
      <geometry>
        <mesh filename="meshes/caster_3.STL" />
      </geometry>
      <material name="">
        <color rgba="0.50196 0.50196 0.50196 1" />
      </material>
    </visual>
  </link>
  
  <joint name="caster_3_joint" type="fixed">
    <origin xyz="0.2325 -1.7275 -0.8325" rpy="1.5708 0 0" />
    <parent link="base_link" />
    <child link="caster_3" />
    <axis xyz="0 0 0" />
  </joint>
  
  <link name="caster_4">
    <visual>
      <origin xyz="0 0 0" rpy="0 0 0" />
      <geometry>
        <mesh filename="meshes/caster_4.STL" />
      </geometry>
      <material name="">
        <color rgba="0.50196 0.50196 0.50196 1" />
      </material>
    </visual>
  </link>
  
  <joint name="caster_4_joint"
    type="fixed">
    <origin xyz="-0.2325 -1.7275 -0.8325" rpy="1.5708 0 0" />
    <parent link="base_link" />
    <child link="caster_4" />
    <axis xyz="0 0 0" />
  </joint>
</robot>